Workbook

Sheet Summary
A1: CAAR Litigation Analytics
A2: Auto-refreshing summary from 953+ records across Mumbai and Delhi CAAR
A4: OVERVIEW
A5: Total Records | B5: =COUNTA('All Records'!A5:A2000)
A6: With PDF Available | B6: =COUNTIF('All Records'!M5:M2000,"YES")
A8: BY SECTION
A9: Section | B9: Count | C9: With PDF | D9: PDF %
A10: Mumbai Rulings | B10: =COUNTA('Mumbai_Rulings'!A5:A2000) | C10: =COUNTIF('Mumbai_Rulings'!M5:M2000,"YES") | D10: =IFERROR(C10/B10,0)
A11: Mumbai Orders | B11: =COUNTA('Mumbai_Orders'!A5:A2000) | C11: =COUNTIF('Mumbai_Orders'!M5:M2000,"YES") | D11: =IFERROR(C11/B11,0)
A12: Delhi Rulings | B12: =COUNTA('Delhi_Rulings'!A5:A2000) | C12: =COUNTIF('Delhi_Rulings'!M5:M2000,"YES") | D12: =IFERROR(C12/B12,0)
A13: Delhi Orders | B13: =COUNTA('Delhi_Orders'!A5:A2000) | C13: =COUNTIF('Delhi_Orders'!M5:M2000,"YES") | D13: =IFERROR(C13/B13,0)
A14: TOTAL | B14: =SUM(B10:B13) | C14: =SUM(C10:C13) | D14: =IFERROR(C14/B14,0)
A16: BY ISSUE TYPE
A17: Issue Type | B17: Count | C17: Share
A18: Classification | B18: =COUNTIF('All Records'!I5:I2000,"Classification") | C18: =IFERROR(B18/40,0)
A19: Unspecified | B19: =COUNTIF('All Records'!I5:I2000,"Unspecified") | C19: =IFERROR(B19/40,0)
A20: Exemption | B20: =COUNTIF('All Records'!I5:I2000,"Exemption") | C20: =IFERROR(B20/40,0)
A22: BY YEAR
A23: Year | B23: Total | C23: Mumbai | D23: Delhi
A24: 2026 | B24: =COUNTIF('All Records'!G5:G2000,"2026") | C24: =COUNTIFS('All Records'!G5:G2000,"2026",'All Records'!A5:A2000,"Mumbai*") | D24: =COUNTIFS('All Records'!G5:G2000,"2026",'All Records'!A5:A2000,"Delhi*")

Sheet All Records
A1: CAAR Litigation Analytics - All Records (All Benches and Types)
A2: 40 records
A4: Section | B4: Pg | C4: Sl | D4: Applicant | E4: Date of Application | F4: Date of Ruling | G4: Year | H4: Subject | I4: Issue Type | J4: Confidence | K4: Ruling No. | L4: PDF Link | M4: PDF?
A5: Mumbai Rulings | B5: 1 | C5: 1 | D5: Siemens Limited | E5: 27.03.2026 | F5: 08.10.2026 | G5: 2026 | H5: Import of the following products for use in manufacture and assembly of Industrial Computing Platfor | I5: Classification | J5: inferred | K5: CAAR/Mum/ARC/106/2026 | L5: https://www.cbic.gov.in/content/pdf/CONTENTREPO/CAAR/caar-Mum-rul-106-12102026.pdf | M5: YES
A6: Mumbai Rulings | B6: 1 | C6: 2 | D6: BPIN Private Limited | E6: 25.02.2026 | F6: 07.10.2026 | G6: 2026 | H6: Import of 'Car Radio Units' in semi-knocked down (SKD) condition | I6: Classification | J6: inferred | K6: CAAR/Mum/ARC/104 & 105/2026 | L6: https://www.cbic.gov.in/content/pdf/CONTENTREPO/CAAR/caar-mum-105-08102026.pdf | M6: YES
A7: Mumbai Rulings | B7: 1 | C7: 3 | D7: Sanmina-SCI India Private Limited | E7: 21.04.2026 | F7: 06.10.2026 | G7: 2026 | H7: Classification of the storage-servers and the applicability of Serial No.39 of Notification No. 24/2 | I7: Exemption | J7: explicit | K7: CAAR/Mum/ARC/102 & 103/2026 | L7: https://www.cbic.gov.in/content/pdf/CONTENTREPO/CAAR/caar-Mum-102-103-08102026.pdf | M7: YES
A8: Mumbai Rulings | B8: 1 | C8: 4 | D8: ORANGE INKJET SOLUTIONS PRIVATE LIMITED | E8: 27.02.2026 | F8: 30.09.2026 | G8: 2026 | H8: Classification of Ink-Jet Printers. | I8: Classification | J8: explicit | K8: CAAR/Mum/ARC/101/2026-27 | M8: NO
A9: Mumbai Rulings | B9: 1 | C9: 5 | D9: Halton India Private Limited | E9: 05.01.2026 | F9: 29.09.2026 | G9: 2026 | H9: classification of "Kitchen Exhaust Hoods with different Models". | I9: Classification | J9: explicit | K9: CAAR/Mum/ARC/100/2026 | L9: https://www.cbic.gov.in/content/pdf/CONTENTREPO/CAAR/CAAR_Mum_ARC_100_2026-27.pdf | M9: YES
A10: Mumbai Rulings | B10: 1 | C10: 6 | D10: M/s.Radiant Enterprises | E10: 03.02.2026 | F10: 28.09.2026 | G10: 2026 | H10: Classification of a) wifi communication modules, (b) cellular communication modules, and (c) navigat | I10: Classification | J10: explicit | K10: CAAR/Mum/ARC/99/2026 | L10: https://www.cbic.gov.in/content/pdf/CONTENTREPO/CAAR/CAAR_Mum_ARC_99_29092026.pdf | M10: YES
A11: Mumbai Rulings | B11: 1 | C11: 7 | D11: M/s.Pinaka Aerospace Solutions Pvt. Ltd. | E11: 17.02.2026 | F11: 25.09.2026 | G11: 2026 | H11: Import of Aircraft components-MILDS F SUOF Lens V2, Front End (M2FE) V2.11 and MILDS F SUII Coupled | I11: Classification | J11: inferred | K11: CAAR/Mum/ARC/98/2026 | L11: https://www.cbic.gov.in/content/pdf/CONTENTREPO/CAAR/CAAR_Mum_ARC_98_29092026.pdf | M11: YES
A12: Mumbai Rulings | B12: 1 | C12: 8 | D12: M/s. Global Exim | E12: 08.07.2026 | F12: 25.09.2026 | G12: 2026 | H12: Classification of product described as 'Pea Protein-85%'. | I12: Classification | J12: explicit | K12: CAAR/Mum/ARC/97/2026-27 | M12: NO
A13: Mumbai Rulings | B13: 1 | C13: 9 | D13: M/s. Global Exim | E13: 08.07.2026 | F13: 25.09.2026 | G13: 2026 | H13: Classification of product described as 'Monk Fruit Extract' | I13: Classification | J13: explicit | K13: CAAR/Mum/ARC/96/2026-27 | M13: NO
A14: Mumbai Rulings | B14: 1 | C14: 10 | D14: M/s. SEYFERT GLOBAL PRIVATE LIMITED | E14: 29.06.2026 | F14: 24.09.2026 | G14: 2026 | H14: Classification of cashew kernels Cashew Nuts Broken (Large and Small Broken Pieces) | I14: Classification | J14: explicit | K14: CAAR/Mum/ARC/95/2026-27 | M14: NO
A15: Mumbai Orders | B15: 1 | C15: 1 | D15: Gangwal Healthcare Private Limited | E15: 27.05.2026 | F15: 13.10.2026 | G15: 2026 | H15: Proposed import 'Avonlac 282' which is the primary raw material for manufacturing the health supplem | I15: Classification | J15: inferred | K15: CAAR/Mum/ARC/54/2026-27 | L15: https://www.cbic.gov.in/content/pdf/CONTENTREPO/CAAR/CAAR_Mum_ARC_54_15102026.pdf | M15: YES
A16: Mumbai Orders | B16: 1 | C16: 2 | D16: M/s. ENVORA EXIM | E16: 13.07.2026 | F16: 08.10.2026 | G16: 2026 | H16: Imports of 'Roasted Areca Nuts- HS code: 2008 1991 | I16: Classification | J16: explicit | K16: CAAR/Mum/ARC/53/2026-27 | L16: https://www.cbic.gov.in/content/pdf/CONTENTREPO/CAAR/caar-mum-ord-53-12102026.pdf | M16: YES
A17: Mumbai Orders | B17: 1 | C17: 3 | D17: Rashi Peripherals Limited | E17: 08.05.2026 | F17: 07.10.2026 | G17: 2026 | H17: Import of 'LTE CAT/GSM Modules'. | I17: Classification | J17: inferred | K17: CAAR/Mum/ARC/52/2026-27 | L17: https://www.cbic.gov.in/content/pdf/CONTENTREPO/CAAR/CAAR_Mum_ARC_52_2026-27.pdf | M17: YES
A18: Mumbai Orders | B18: 1 | C18: 4 | D18: TECEX INDIA PRIVATE LIMITED | E18: 12.01.2026 | F18: 06.10.2026 | G18: 2026 | H18: Classification of Integrated Rack Server | I18: Classification | J18: explicit | K18: CAAR/Mum/ARC/51/2026-27 | L18: https://www.cbic.gov.in/content/pdf/CONTENTREPO/CAAR/caar-mum-ord-51-08102026.pdf | M18: YES
A19: Mumbai Orders | B19: 1 | C19: 5 | D19: M/s Melfa Trading Impex Private Limited | E19: 07.05.2026 | F19: 30.09.2026 | G19: 2026 | H19: Import of 'Oven Roasted Areca Nuts' | I19: Classification | J19: inferred | K19: CAAR/Mum/ARC/48, 49 & 50/2026-27 | L19: https://www.cbic.gov.in/content/pdf/CONTENTREPO/CAAR/CAAR_Mum_Melfa_Trading_48_49_50_05102026.pdf | M19: YES
A20: Mumbai Orders | B20: 1 | C20: 6 | D20: SAI KRIPA ENTERPRISES | E20: 07.04.2026 | F20: 28.09.2026 | G20: 2026 | H20: Import of Inshell Walnuts under Transferable DFIA issued against export of Assorted Confectionery Go | I20: Classification | J20: inferred | K20: CAAR/Mum/ARC/47/2026-27 | L20: https://www.cbic.gov.in/content/pdf/CONTENTREPO/CAAR/CAAR_Mum_ARC_47_2026-27.pdf | M20: YES
A21: Mumbai Orders | B21: 1 | C21: 7 | D21: M/s Global Exim | E21: 07.04.2026 | F21: 11.09.2026 | G21: 2026 | H21: Import of 'Roasted Areca Nuts' | I21: Classification | J21: inferred | K21: CAAR/Mum/ARC/45 & 46/2026-27 | L21: https://www.cbic.gov.in/content/pdf/CONTENTREPO/CAAR/CAAR_Mum_ARC_45_46_15092026.pdf | M21: YES
A22: Mumbai Orders | B22: 1 | C22: 8 | D22: M/s.WEBINTOSH TECHNOLOGIES PRIVATE LIMITED | E22: 04.06.2026 | F22: 10.09.2026 | G22: 2026 | H22: Classification of the 'Roasted Areca Nuts (Whole) and Roasted Areca Nuts (Cut)' | I22: Classification | J22: explicit | K22: CAAR/Mum/ARC/44/2026-27 | M22: NO
A23: Mumbai Orders | B23: 1 | C23: 9 | D23: ARABIAN SEA MULTITRADE PVT. LTD | E23: 10.06.2026 | F23: 03.09.2026 | G23: 2026 | H23: seeking classification of the import of Roasted Areca Nuts (whole), Roasted Areca Nuts (Split), Roas | I23: Classification | J23: explicit | K23: CAAR/Mum/ARC/40,41,42 & 43/2026-27 | L23: https://www.cbic.gov.in/content/pdf/CONTENTREPO/CAAR/CAAR_Mum_ARC_40-41-42-43_07092026.pdf | M23: YES
A24: Mumbai Orders | B24: 1 | C24: 10 | D24: M/s Jineshwar Impex | E24: 22.06.2026 | F24: 27.08.2026 | G24: 2026 | H24: Seeking classification of the "Roasted Areca Nuts (Whole/ Split/ Cut)". | I24: Classification | J24: explicit | K24: CAAR/Mum/ARC/36,37,38 & 39/2026-27 | L24: https://www.cbic.gov.in/content/pdf/CONTENTREPO/CAAR/CAAR_Mum_ARC_36-37-38-39_28082026.pdf | M24: YES
A25: Delhi Rulings | B25: 1 | C25: 1 | D25: M/s Adit Infratel Private Ltd | E25: 03.07.2026 | F25: 07.10.2026 | G25: 2026 | H25: Availment of benefit of Serial No. 321 of Notification No. 45/2025- in respect of imported lithium-i | I25: Exemption | J25: explicit | K25: CAAR/DEL/ Adit Infratel/58/2026-27 | M25: NO
A26: Delhi Rulings | B26: 1 | C26: 2 | D26: M/s. Sunwoda Electronic India Private Limited | E26: 24.06.2026 | F26: 05.10.2026 | G26: 2026 | H26: Classification of Die Cut Tape and Tape in Roll used in manufacturing of lithium-ion batteries and E | I26: Classification | J26: explicit | K26: CAAR/Del/Sunwoda/55-57/2026-27 | L26: https://www.cbic.gov.in/content/pdf/CONTENTREPO/CAAR/CAAR_Del_Sunwoda_55_57_06102026.pdf | M26: YES
A27: Delhi Rulings | B27: 1 | C27: 3 | D27: M/s. Sony India Private Limited | E27: 22.05.2026 | F27: 29.09.2026 | G27: 2026 | H27: Classification of Various types of print media/sheets, namely UPP-110 HG, UPP-110S, UPP-110HD, UPP-8 | I27: Classification | J27: explicit | K27: CAAR/Del/Sony/54/2026-27 | M27: NO
A28: Delhi Rulings | B28: 1 | C28: 4 | D28: M/s. Samsung India Electronics Private Limited | E28: 30.03.2026 | F28: 24.09.2026 | G28: 2026 | H28: Classification of LCD Display Assembly having Product Code No. GH96-16566A and OLED Display Assembly | I28: Classification | J28: explicit | K28: CAAR/Del/Samsung/53/2026-27 | M28: NO
A29: Delhi Rulings | B29: 1 | C29: 5 | D29: M/s Mediraw Pharma & Nutra Private Limited | E29: 01.04.2026 | F29: 24.09.2026 | G29: 2026 | H29: Classification of AstaReal(Natural Astaxanthin). | I29: Classification | J29: explicit | K29: CAAR/Del/Mediraw/52/2026-27 | L29: https://www.cbic.gov.in/content/pdf/CONTENTREPO/CAAR/CAAR_Del_Mediraw_52_25092026.pdf | M29: YES
A30: Delhi Rulings | B30: 1 | C30: 6 | D30: M/s Adit Infratel Private Ltd | E30: 03.07.2026 | F30: 17.09.2026 | G30: 2026 | I30: Unspecified | J30: low | K30: CAAR/DEL/Adit Infratel/51/2026-27 | L30: https://www.cbic.gov.in/content/pdf/CONTENTREPO/CAAR/caar-del-51-18092026.pdf | M30: YES
A31: Delhi Rulings | B31: 1 | C31: 7 | D31: M/s OPPO Mobiles India Private Limited | E31: 07.04.2026 | F31: 31.08.2026 | G31: 2026 | H31: Classification of Back Cover Assembly with Battery of Tablet PCs | I31: Classification | J31: explicit | K31: CAAR/Del/OPPO/50/2026-27 | L31: https://www.cbic.gov.in/content/pdf/CONTENTREPO/CAAR/caar-del-50-08092026.pdf | M31: YES
A32: Delhi Rulings | B32: 1 | C32: 8 | D32: M/s Canon India Pvt Ltd | E32: 30.03.2026 | F32: 27.08.2026 | G32: 2026 | I32: Unspecified | J32: low | K32: CAAR/DEL/Canon/49/2026-27 | M32: NO
A33: Delhi Rulings | B33: 1 | C33: 9 | D33: M/s Volvo Auto India Private Limited | E33: 20.05.2026 | F33: 24.08.2026 | G33: 2026 | H33: Classification of the unassembled knocked-down kit of the electrically operated vehicle Models “EX-9 | I33: Classification | J33: explicit | K33: CAAR/Del/Volvo/48/2026-27 | M33: NO
A34: Delhi Rulings | B34: 1 | C34: 10 | D34: M/s Mankind Pharma Limited | E34: 04.05.2026 | F34: 19.08.2026 | G34: 2026 | H34: IGST leviable on Import of bulk drugs/ API (Active pharmaceutical ingredients). | I34: Classification | J34: inferred | K34: CAAR/Del/Mankind/44-45/2026 | L34: https://www.cbic.gov.in/content/pdf/CONTENTREPO/CAAR/CAAR_Del_ARC_44-45_25082026.pdf | M34: YES
A35: Delhi Orders | B35: 1 | C35: 1 | D35: M/s Vardhman Vanijya Pvt. Ltd., | E35: 10.07.2026 | F35: 09.10.2026 | G35: 2026 | H35: Roasted Betel nut/ Areca Nuts - Whole/ Cut | I35: Classification | J35: inferred | K35: CAAR/Del/Vardhman/57/2026-27 | L35: https://www.cbic.gov.in/content/pdf/CONTENTREPO/CAAR/caar-del-ord-57-12102026.pdf | M35: YES
A36: Delhi Orders | B36: 1 | C36: 2 | D36: M/s Apple Operations International Limited | E36: 22.07.2026 | F36: 05.10.2026 | G36: 2026 | H36: Classification of 'IC Modules under the First Schedule of the Customs Tariff Act, 1975' | I36: Classification | J36: explicit | K36: CAAR/Del/Apple/54-56/2026-27 | L36: https://www.cbic.gov.in/content/pdf/CONTENTREPO/CAAR/CAAR_Del_Apple_54_56_06102026.pdf | M36: YES
A37: Delhi Orders | B37: 1 | C37: 3 | D37: M/s S.R. Sales | E37: 24.06.2026 | F37: 01.10.2026 | G37: 2026 | H37: Roasted Areca Nuts. | I37: Classification | J37: inferred | K37: CAAR/Del/S.R.Sales/49-53/2026-27 | L37: https://www.cbic.gov.in/content/pdf/CONTENTREPO/CAAR/CAAR_Del_SR_Sales_49_53_05102026.pdf | M37: YES
A38: Delhi Orders | B38: 1 | C38: 4 | D38: M/s AS Spices | E38: 01.07.2026 | F38: 01.10.2026 | G38: 2026 | H38: Roasted Areca Nuts. | I38: Classification | J38: inferred | K38: CAAR/Del/AS Spices/46-48/2026-27 | L38: https://www.cbic.gov.in/content/pdf/CONTENTREPO/CAAR/CAAR_Del_ASSpices_46_48_05102026.pdf | M38: YES
A39: Delhi Orders | B39: 1 | C39: 5 | D39: M/s Ganpati Traders | E39: 12.06.2026 | F39: 18.09.2026 | G39: 2026 | I39: Unspecified | J39: low | K39: CAAR/Del/Ganpati/41-45/2026-27 | L39: https://www.cbic.gov.in/content/pdf/CONTENTREPO/CAAR/CAAR_Del_Ganpati_41-45_2026-27.pdf | M39: YES
A40: Delhi Orders | B40: 1 | C40: 6 | D40: M/s Dira Impex, | E40: 19.06.2026 | F40: 10.09.2026 | G40: 2026 | H40: Roasted Areca Nuts - Whole, Split, Cut | I40: Classification | J40: inferred | K40: CAAR/DEL/Dira Impex/40/2026-27 | L40: https://www.cbic.gov.in/content/pdf/CONTENTREPO/CAAR/caar-del-ord-40-28092026.pdf | M40: YES
A41: Delhi Orders | B41: 1 | C41: 7 | D41: M/s Golden Enterprises | E41: 08.05.2026 | F41: 03.06.2026 | G41: 2026 | I41: Unspecified | J41: low | K41: CAAR/Del/Golden/37-39/2026-27 | L41: https://www.cbic.gov.in/content/pdf/CONTENTREPO/CAAR/CAAR_Del_Golden_37-39_2026-27.pdf | M41: YES
...

Sheet Mumbai_Rulings
A1: CAAR Litigation Analytics - Mumbai Rulings
A2: 10 records
A4: Section | B4: Pg | C4: Sl | D4: Applicant | E4: Date of Application | F4: Date of Ruling | G4: Year | H4: Subject | I4: Issue Type | J4: Confidence | K4: Ruling No. | L4: PDF Link | M4: PDF?
A5: Mumbai Rulings | B5: 1 | C5: 1 | D5: Siemens Limited | E5: 27.03.2026 | F5: 08.10.2026 | G5: 2026 | H5: Import of the following products for use in manufacture and assembly of Industrial Computing Platfor | I5: Classification | J5: inferred | K5: CAAR/Mum/ARC/106/2026 | L5: https://www.cbic.gov.in/content/pdf/CONTENTREPO/CAAR/caar-Mum-rul-106-12102026.pdf | M5: YES
A6: Mumbai Rulings | B6: 1 | C6: 2 | D6: BPIN Private Limited | E6: 25.02.2026 | F6: 07.10.2026 | G6: 2026 | H6: Import of 'Car Radio Units' in semi-knocked down (SKD) condition | I6: Classification | J6: inferred | K6: CAAR/Mum/ARC/104 & 105/2026 | L6: https://www.cbic.gov.in/content/pdf/CONTENTREPO/CAAR/caar-mum-105-08102026.pdf | M6: YES
A7: Mumbai Rulings | B7: 1 | C7: 3 | D7: Sanmina-SCI India Private Limited | E7: 21.04.2026 | F7: 06.10.2026 | G7: 2026 | H7: Classification of the storage-servers and the applicability of Serial No.39 of Notification No. 24/2 | I7: Exemption | J7: explicit | K7: CAAR/Mum/ARC/102 & 103/2026 | L7: https://www.cbic.gov.in/content/pdf/CONTENTREPO/CAAR/caar-Mum-102-103-08102026.pdf | M7: YES
A8: Mumbai Rulings | B8: 1 | C8: 4 | D8: ORANGE INKJET SOLUTIONS PRIVATE LIMITED | E8: 27.02.2026 | F8: 30.09.2026 | G8: 2026 | H8: Classification of Ink-Jet Printers. | I8: Classification | J8: explicit | K8: CAAR/Mum/ARC/101/2026-27 | M8: NO
A9: Mumbai Rulings | B9: 1 | C9: 5 | D9: Halton India Private Limited | E9: 05.01.2026 | F9: 29.09.2026 | G9: 2026 | H9: classification of "Kitchen Exhaust Hoods with different Models". | I9: Classification | J9: explicit | K9: CAAR/Mum/ARC/100/2026 | L9: https://www.cbic.gov.in/content/pdf/CONTENTREPO/CAAR/CAAR_Mum_ARC_100_2026-27.pdf | M9: YES
A10: Mumbai Rulings | B10: 1 | C10: 6 | D10: M/s.Radiant Enterprises | E10: 03.02.2026 | F10: 28.09.2026 | G10: 2026 | H10: Classification of a) wifi communication modules, (b) cellular communication modules, and (c) navigat | I10: Classification | J10: explicit | K10: CAAR/Mum/ARC/99/2026 | L10: https://www.cbic.gov.in/content/pdf/CONTENTREPO/CAAR/CAAR_Mum_ARC_99_29092026.pdf | M10: YES
A11: Mumbai Rulings | B11: 1 | C11: 7 | D11: M/s.Pinaka Aerospace Solutions Pvt. Ltd. | E11: 17.02.2026 | F11: 25.09.2026 | G11: 2026 | H11: Import of Aircraft components-MILDS F SUOF Lens V2, Front End (M2FE) V2.11 and MILDS F SUII Coupled | I11: Classification | J11: inferred | K11: CAAR/Mum/ARC/98/2026 | L11: https://www.cbic.gov.in/content/pdf/CONTENTREPO/CAAR/CAAR_Mum_ARC_98_29092026.pdf | M11: YES
A12: Mumbai Rulings | B12: 1 | C12: 8 | D12: M/s. Global Exim | E12: 08.07.2026 | F12: 25.09.2026 | G12: 2026 | H12: Classification of product described as 'Pea Protein-85%'. | I12: Classification | J12: explicit | K12: CAAR/Mum/ARC/97/2026-27 | M12: NO
A13: Mumbai Rulings | B13: 1 | C13: 9 | D13: M/s. Global Exim | E13: 08.07.2026 | F13: 25.09.2026 | G13: 2026 | H13: Classification of product described as 'Monk Fruit Extract' | I13: Classification | J13: explicit | K13: CAAR/Mum/ARC/96/2026-27 | M13: NO
A14: Mumbai Rulings | B14: 1 | C14: 10 | D14: M/s. SEYFERT GLOBAL PRIVATE LIMITED | E14: 29.06.2026 | F14: 24.09.2026 | G14: 2026 | H14: Classification of cashew kernels Cashew Nuts Broken (Large and Small Broken Pieces) | I14: Classification | J14: explicit | K14: CAAR/Mum/ARC/95/2026-27 | M14: NO

Sheet Mumbai_Orders
A1: CAAR Litigation Analytics - Mumbai Orders
A2: 10 records
A4: Section | B4: Pg | C4: Sl | D4: Applicant | E4: Date of Application | F4: Date of Ruling | G4: Year | H4: Subject | I4: Issue Type | J4: Confidence | K4: Ruling No. | L4: PDF Link | M4: PDF?
A5: Mumbai Orders | B5: 1 | C5: 1 | D5: Gangwal Healthcare Private Limited | E5: 27.05.2026 | F5: 13.10.2026 | G5: 2026 | H5: Proposed import 'Avonlac 282' which is the primary raw material for manufacturing the health supplem | I5: Classification | J5: inferred | K5: CAAR/Mum/ARC/54/2026-27 | L5: https://www.cbic.gov.in/content/pdf/CONTENTREPO/CAAR/CAAR_Mum_ARC_54_15102026.pdf | M5: YES
A6: Mumbai Orders | B6: 1 | C6: 2 | D6: M/s. ENVORA EXIM | E6: 13.07.2026 | F6: 08.10.2026 | G6: 2026 | H6: Imports of 'Roasted Areca Nuts- HS code: 2008 1991 | I6: Classification | J6: explicit | K6: CAAR/Mum/ARC/53/2026-27 | L6: https://www.cbic.gov.in/content/pdf/CONTENTREPO/CAAR/caar-mum-ord-53-12102026.pdf | M6: YES
A7: Mumbai Orders | B7: 1 | C7: 3 | D7: Rashi Peripherals Limited | E7: 08.05.2026 | F7: 07.10.2026 | G7: 2026 | H7: Import of 'LTE CAT/GSM Modules'. | I7: Classification | J7: inferred | K7: CAAR/Mum/ARC/52/2026-27 | L7: https://www.cbic.gov.in/content/pdf/CONTENTREPO/CAAR/CAAR_Mum_ARC_52_2026-27.pdf | M7: YES
A8: Mumbai Orders | B8: 1 | C8: 4 | D8: TECEX INDIA PRIVATE LIMITED | E8: 12.01.2026 | F8: 06.10.2026 | G8: 2026 | H8: Classification of Integrated Rack Server | I8: Classification | J8: explicit | K8: CAAR/Mum/ARC/51/2026-27 | L8: https://www.cbic.gov.in/content/pdf/CONTENTREPO/CAAR/caar-mum-ord-51-08102026.pdf | M8: YES
A9: Mumbai Orders | B9: 1 | C9: 5 | D9: M/s Melfa Trading Impex Private Limited | E9: 07.05.2026 | F9: 30.09.2026 | G9: 2026 | H9: Import of 'Oven Roasted Areca Nuts' | I9: Classification | J9: inferred | K9: CAAR/Mum/ARC/48, 49 & 50/2026-27 | L9: https://www.cbic.gov.in/content/pdf/CONTENTREPO/CAAR/CAAR_Mum_Melfa_Trading_48_49_50_05102026.pdf | M9: YES
A10: Mumbai Orders | B10: 1 | C10: 6 | D10: SAI KRIPA ENTERPRISES | E10: 07.04.2026 | F10: 28.09.2026 | G10: 2026 | H10: Import of Inshell Walnuts under Transferable DFIA issued against export of Assorted Confectionery Go | I10: Classification | J10: inferred | K10: CAAR/Mum/ARC/47/2026-27 | L10: https://www.cbic.gov.in/content/pdf/CONTENTREPO/CAAR/CAAR_Mum_ARC_47_2026-27.pdf | M10: YES
A11: Mumbai Orders | B11: 1 | C11: 7 | D11: M/s Global Exim | E11: 07.04.2026 | F11: 11.09.2026 | G11: 2026 | H11: Import of 'Roasted Areca Nuts' | I11: Classification | J11: inferred | K11: CAAR/Mum/ARC/45 & 46/2026-27 | L11: https://www.cbic.gov.in/content/pdf/CONTENTREPO/CAAR/CAAR_Mum_ARC_45_46_15092026.pdf | M11: YES
A12: Mumbai Orders | B12: 1 | C12: 8 | D12: M/s.WEBINTOSH TECHNOLOGIES PRIVATE LIMITED | E12: 04.06.2026 | F12: 10.09.2026 | G12: 2026 | H12: Classification of the 'Roasted Areca Nuts (Whole) and Roasted Areca Nuts (Cut)' | I12: Classification | J12: explicit | K12: CAAR/Mum/ARC/44/2026-27 | M12: NO
A13: Mumbai Orders | B13: 1 | C13: 9 | D13: ARABIAN SEA MULTITRADE PVT. LTD | E13: 10.06.2026 | F13: 03.09.2026 | G13: 2026 | H13: seeking classification of the import of Roasted Areca Nuts (whole), Roasted Areca Nuts (Split), Roas | I13: Classification | J13: explicit | K13: CAAR/Mum/ARC/40,41,42 & 43/2026-27 | L13: https://www.cbic.gov.in/content/pdf/CONTENTREPO/CAAR/CAAR_Mum_ARC_40-41-42-43_07092026.pdf | M13: YES
A14: Mumbai Orders | B14: 1 | C14: 10 | D14: M/s Jineshwar Impex | E14: 22.06.2026 | F14: 27.08.2026 | G14: 2026 | H14: Seeking classification of the "Roasted Areca Nuts (Whole/ Split/ Cut)". | I14: Classification | J14: explicit | K14: CAAR/Mum/ARC/36,37,38 & 39/2026-27 | L14: https://www.cbic.gov.in/content/pdf/CONTENTREPO/CAAR/CAAR_Mum_ARC_36-37-38-39_28082026.pdf | M14: YES

Sheet Delhi_Rulings
A1: CAAR Litigation Analytics - Delhi Rulings
A2: 10 records
A4: Section | B4: Pg | C4: Sl | D4: Applicant | E4: Date of Application | F4: Date of Ruling | G4: Year | H4: Subject | I4: Issue Type | J4: Confidence | K4: Ruling No. | L4: PDF Link | M4: PDF?
A5: Delhi Rulings | B5: 1 | C5: 1 | D5: M/s Adit Infratel Private Ltd | E5: 03.07.2026 | F5: 07.10.2026 | G5: 2026 | H5: Availment of benefit of Serial No. 321 of Notification No. 45/2025- in respect of imported lithium-i | I5: Exemption | J5: explicit | K5: CAAR/DEL/ Adit Infratel/58/2026-27 | M5: NO
A6: Delhi Rulings | B6: 1 | C6: 2 | D6: M/s. Sunwoda Electronic India Private Limited | E6: 24.06.2026 | F6: 05.10.2026 | G6: 2026 | H6: Classification of Die Cut Tape and Tape in Roll used in manufacturing of lithium-ion batteries and E | I6: Classification | J6: explicit | K6: CAAR/Del/Sunwoda/55-57/2026-27 | L6: https://www.cbic.gov.in/content/pdf/CONTENTREPO/CAAR/CAAR_Del_Sunwoda_55_57_06102026.pdf | M6: YES
A7: Delhi Rulings | B7: 1 | C7: 3 | D7: M/s. Sony India Private Limited | E7: 22.05.2026 | F7: 29.09.2026 | G7: 2026 | H7: Classification of Various types of print media/sheets, namely UPP-110 HG, UPP-110S, UPP-110HD, UPP-8 | I7: Classification | J7: explicit | K7: CAAR/Del/Sony/54/2026-27 | M7: NO
A8: Delhi Rulings | B8: 1 | C8: 4 | D8: M/s. Samsung India Electronics Private Limited | E8: 30.03.2026 | F8: 24.09.2026 | G8: 2026 | H8: Classification of LCD Display Assembly having Product Code No. GH96-16566A and OLED Display Assembly | I8: Classification | J8: explicit | K8: CAAR/Del/Samsung/53/2026-27 | M8: NO
A9: Delhi Rulings | B9: 1 | C9: 5 | D9: M/s Mediraw Pharma & Nutra Private Limited | E9: 01.04.2026 | F9: 24.09.2026 | G9: 2026 | H9: Classification of AstaReal(Natural Astaxanthin). | I9: Classification | J9: explicit | K9: CAAR/Del/Mediraw/52/2026-27 | L9: https://www.cbic.gov.in/content/pdf/CONTENTREPO/CAAR/CAAR_Del_Mediraw_52_25092026.pdf | M9: YES
A10: Delhi Rulings | B10: 1 | C10: 6 | D10: M/s Adit Infratel Private Ltd | E10: 03.07.2026 | F10: 17.09.2026 | G10: 2026 | I10: Unspecified | J10: low | K10: CAAR/DEL/Adit Infratel/51/2026-27 | L10: https://www.cbic.gov.in/content/pdf/CONTENTREPO/CAAR/caar-del-51-18092026.pdf | M10: YES
A11: Delhi Rulings | B11: 1 | C11: 7 | D11: M/s OPPO Mobiles India Private Limited | E11: 07.04.2026 | F11: 31.08.2026 | G11: 2026 | H11: Classification of Back Cover Assembly with Battery of Tablet PCs | I11: Classification | J11: explicit | K11: CAAR/Del/OPPO/50/2026-27 | L11: https://www.cbic.gov.in/content/pdf/CONTENTREPO/CAAR/caar-del-50-08092026.pdf | M11: YES
A12: Delhi Rulings | B12: 1 | C12: 8 | D12: M/s Canon India Pvt Ltd | E12: 30.03.2026 | F12: 27.08.2026 | G12: 2026 | I12: Unspecified | J12: low | K12: CAAR/DEL/Canon/49/2026-27 | M12: NO
A13: Delhi Rulings | B13: 1 | C13: 9 | D13: M/s Volvo Auto India Private Limited | E13: 20.05.2026 | F13: 24.08.2026 | G13: 2026 | H13: Classification of the unassembled knocked-down kit of the electrically operated vehicle Models “EX-9 | I13: Classification | J13: explicit | K13: CAAR/Del/Volvo/48/2026-27 | M13: NO
A14: Delhi Rulings | B14: 1 | C14: 10 | D14: M/s Mankind Pharma Limited | E14: 04.05.2026 | F14: 19.08.2026 | G14: 2026 | H14: IGST leviable on Import of bulk drugs/ API (Active pharmaceutical ingredients). | I14: Classification | J14: inferred | K14: CAAR/Del/Mankind/44-45/2026 | L14: https://www.cbic.gov.in/content/pdf/CONTENTREPO/CAAR/CAAR_Del_ARC_44-45_25082026.pdf | M14: YES

Sheet Delhi_Orders
A1: CAAR Litigation Analytics - Delhi Orders
A2: 10 records
A4: Section | B4: Pg | C4: Sl | D4: Applicant | E4: Date of Application | F4: Date of Ruling | G4: Year | H4: Subject | I4: Issue Type | J4: Confidence | K4: Ruling No. | L4: PDF Link | M4: PDF?
A5: Delhi Orders | B5: 1 | C5: 1 | D5: M/s Vardhman Vanijya Pvt. Ltd., | E5: 10.07.2026 | F5: 09.10.2026 | G5: 2026 | H5: Roasted Betel nut/ Areca Nuts - Whole/ Cut | I5: Classification | J5: inferred | K5: CAAR/Del/Vardhman/57/2026-27 | L5: https://www.cbic.gov.in/content/pdf/CONTENTREPO/CAAR/caar-del-ord-57-12102026.pdf | M5: YES
A6: Delhi Orders | B6: 1 | C6: 2 | D6: M/s Apple Operations International Limited | E6: 22.07.2026 | F6: 05.10.2026 | G6: 2026 | H6: Classification of 'IC Modules under the First Schedule of the Customs Tariff Act, 1975' | I6: Classification | J6: explicit | K6: CAAR/Del/Apple/54-56/2026-27 | L6: https://www.cbic.gov.in/content/pdf/CONTENTREPO/CAAR/CAAR_Del_Apple_54_56_06102026.pdf | M6: YES
A7: Delhi Orders | B7: 1 | C7: 3 | D7: M/s S.R. Sales | E7: 24.06.2026 | F7: 01.10.2026 | G7: 2026 | H7: Roasted Areca Nuts. | I7: Classification | J7: inferred | K7: CAAR/Del/S.R.Sales/49-53/2026-27 | L7: https://www.cbic.gov.in/content/pdf/CONTENTREPO/CAAR/CAAR_Del_SR_Sales_49_53_05102026.pdf | M7: YES
A8: Delhi Orders | B8: 1 | C8: 4 | D8: M/s AS Spices | E8: 01.07.2026 | F8: 01.10.2026 | G8: 2026 | H8: Roasted Areca Nuts. | I8: Classification | J8: inferred | K8: CAAR/Del/AS Spices/46-48/2026-27 | L8: https://www.cbic.gov.in/content/pdf/CONTENTREPO/CAAR/CAAR_Del_ASSpices_46_48_05102026.pdf | M8: YES
A9: Delhi Orders | B9: 1 | C9: 5 | D9: M/s Ganpati Traders | E9: 12.06.2026 | F9: 18.09.2026 | G9: 2026 | I9: Unspecified | J9: low | K9: CAAR/Del/Ganpati/41-45/2026-27 | L9: https://www.cbic.gov.in/content/pdf/CONTENTREPO/CAAR/CAAR_Del_Ganpati_41-45_2026-27.pdf | M9: YES
A10: Delhi Orders | B10: 1 | C10: 6 | D10: M/s Dira Impex, | E10: 19.06.2026 | F10: 10.09.2026 | G10: 2026 | H10: Roasted Areca Nuts - Whole, Split, Cut | I10: Classification | J10: inferred | K10: CAAR/DEL/Dira Impex/40/2026-27 | L10: https://www.cbic.gov.in/content/pdf/CONTENTREPO/CAAR/caar-del-ord-40-28092026.pdf | M10: YES
A11: Delhi Orders | B11: 1 | C11: 7 | D11: M/s Golden Enterprises | E11: 08.05.2026 | F11: 03.06.2026 | G11: 2026 | I11: Unspecified | J11: low | K11: CAAR/Del/Golden/37-39/2026-27 | L11: https://www.cbic.gov.in/content/pdf/CONTENTREPO/CAAR/CAAR_Del_Golden_37-39_2026-27.pdf | M11: YES
A12: Delhi Orders | B12: 1 | C12: 8 | D12: M/s Empire Exports | E12: 14.05.2026 | F12: 04.08.2026 | G12: 2026 | H12: Roasted Areca Nut and Roasted Areca Nut Split | I12: Classification | J12: inferred | K12: CAAR/DEL/Empire/33-36/2026-27 | M12: NO
A13: Delhi Orders | B13: 1 | C13: 9 | D13: Samkwang india Electronics Private Ltd | E13: 17.03.2026 | F13: 31.07.2026 | G13: 2026 | I13: Unspecified | J13: low | K13: CAAR/Del/Samkwang/32/2026-27 | L13: https://www.cbic.gov.in/content/pdf/CONTENTREPO/CAAR/caar-del-order-32-04082026.pdf | M13: YES
A14: Delhi Orders | B14: 1 | C14: 10 | D14: M/s Ram Charan Barui Enterprise, | E14: 27.04.2026 | F14: 20.07.2026 | G14: 2026 | H14: classification of product namely ‘Roasted Betelnut/Areca Nut(whole/cut)’ | I14: Classification | J14: explicit | K14: CAAR/Del/Ram Charan Barui Enterprise./31/2026 | M14: NO
